File: inst/extdata/MB120718Si3.ras
*RAS_DATA_START
*RAS_HEADER_START
*DISP_FMT_X "%.2f"
*DISP_FMT_Y "%.0f"
*DISP_FULLSCALE "687.2046452403"
*DISP_LINE_COLOR "255.0000000000"
*DISP_LINE_STYLE "0.0000000000"
*DISP_LINE_WIDTH "0.2500000000"
*DISP_NOTE "Collected Data-11"
*DISP_OFFSET_Y "0.0000000000"
*DISP_PEAKSEARCH_UNIT_Y "cps"
*DISP_RANGE_BOTTOM "-432.5080846559"
*DISP_RANGE_LEFT "27.2093453401"
*DISP_RANGE_LOGCUTOFF "0.0100000000"
*DISP_RANGE_RIGHT "31.0324181026"
*DISP_RANGE_TOP "687.2046452403"
*DISP_SCALE_MODE_Y "0.0000000000"
*DISP_TAB_NAME "2-Theta"
*DISP_TITLE_Y "Intensity"
*DISP_UNIT_Y "cps"
*DISP_WINDOW_NAME "MSG_MACROENGINE"
*FILE_COMMENT " "
*FILE_MD5 ""
*FILE_MEMO "[H2Pc/FePc]x4/Si N=4 Multilayer, 160*C Dep. Temp., 72 nm Total Thickness"
*FILE_OPERATOR "Administrator"
*FILE_SAMPLE "MB120718Si3"
*FILE_TYPE "RAS_RAW"
*FILE_USERGROUP "System Manager"
*FILE_VERSION "1.0000000000"
*HW_ATTACHMENT_ID "ATT0025"
*HW_ATTACHMENT_NAME "Standard|Standard"
*HW_COUNTER_ID-0 "CUT0021"
*HW_COUNTER_ID-1 "CUT0020"
*HW_COUNTER_ID-2 ""
*HW_COUNTER_ID-3 "CSL0021"
*HW_COUNTER_ID-4 "CMC0021"
*HW_COUNTER_NAME-0 "SC-70|SC-70"
*HW_COUNTER_NAME-1 "None|None"
*HW_COUNTER_NAME-2 ""
*HW_COUNTER_NAME-3 "BBM|BBM"
*HW_COUNTER_NAME-4 "検出器モノクロメータ|Detector monochromator"
*HW_COUNTER_SELECT_NAME "SC-70|SC-70"
*HW_ECP_HV "638.0000000000"
*HW_ECP_HV_UNIT "V"
*HW_GONIOMETER_ID "GON0023"
*HW_GONIOMETER_NAME "SmartLab|SmartLab"
*HW_GONIOMETER_RADIUS-0 "90.0"
*HW_GONIOMETER_RADIUS-1 "114.0"
*HW_GONIOMETER_RADIUS-2 "190.0"
*HW_GONIOMETER_RADIUS-3 "300.0"
*HW_GONIOMETER_RADIUS-4 "187.0"
*HW_GONIOMETER_RADIUS-5 "300.0"
*HW_GONIOMETER_RADIUS-6 "113.0"
*HW_GONIOMETER_RADIUS-7 "331.0"
*HW_I_OPT_ID-0 "CBO0021"
*HW_I_OPT_ID-1 "ICR0023"
*HW_I_OPT_ID-2 "ISL0021"
*HW_I_OPT_ID-3 "ISO0021"
*HW_I_OPT_ID-4 "IAD0021"
*HW_I_OPT_ID-5 "IPR0001"
*HW_I_OPT_NAME-0 "CBOユニット|CBO unit"
*HW_I_OPT_NAME-1 "標準入射光学ユニット|Standard incident optical unit"
*HW_I_OPT_NAME-2 "標準入射スリットボックス|Standard incident slit box"
*HW_I_OPT_NAME-3 "入射平行スリット|Incident parallel slit"
*HW_I_OPT_NAME-4 "長手制限スリット|Length limiting slit"
*HW_I_OPT_NAME-5 "None|None"
*HW_R_ATTENUATER_AUTOMODE "0"
*HW_R_OPT_ID-0 "RSS0021"
*HW_R_OPT_ID-1 "RCR0022"
*HW_R_OPT_ID-2 "RSO0021"
*HW_R_OPT_ID-3 "RRS0021"
*HW_R_OPT_ID-4 "ATN0021"
*HW_R_OPT_ID-5 "RFL0021"
*HW_R_OPT_ID-6 "RAD0021"
*HW_R_OPT_NAME-0 "標準受光スリットボックス1|Standard receiving slit box # 1"
*HW_R_OPT_NAME-1 "標準受光光学ユニット1|Standard receiving unit # 1"
*HW_R_OPT_NAME-2 "標準受光光学ユニット2|Standard receiving optical unit # 2"
*HW_R_OPT_NAME-3 "標準受光スリットボックス2|Standard receiving slit box # 2"
*HW_R_OPT_NAME-4 "標準アッテネータ|Standard Attenuator"
*HW_R_OPT_NAME-5 "Cu Kβ|Cu K-beta"
*HW_R_OPT_NAME-6 "調整用受光スリット|Alignment receiving slit"
*HW_SAMPLE_HOLDER_ID "SMP0023"
*HW_SAMPLE_HOLDER_NAME "標準Zステージ|Standard Z stage"
*HW_XG_CURRENT_MAX "50"
*HW_XG_CURRENT_MIN "2"
*HW_XG_CURRENT_RESOLUTION "2"
*HW_XG_CURRENT_UNIT "mA"
*HW_XG_FOCUS "1mm x 10mm"
*HW_XG_FOCUS_TYPE "Normal"
*HW_XG_ID ""
*HW_XG_NAME "3kW 封入管(ID:1200)|3kW Sealed tube(ID:1200)"
*HW_XG_TARGET_ATOMIC_NUMBER "29.0000000000"
*HW_XG_TARGET_NAME "Cu"
*HW_XG_TYPE "Hermetic"
*HW_XG_VOLTAGE_MAX "60"
*HW_XG_VOLTAGE_MIN "20"
*HW_XG_VOLTAGE_RESOLUTION "2"
*HW_XG_VOLTAGE_UNIT "kV"
*HW_XG_WATT_MAX "2"
*HW_XG_WATT_UNIT "kW"
*HW_XG_WAVE_LENGTH_ALPHA1 "1.540593"
*HW_XG_WAVE_LENGTH_ALPHA2 "1.544414"
*HW_XG_WAVE_LENGTH_BETA "1.392250"
*MEAS_COND_AXIS_NAME-0 "Theta/2-Theta"
*MEAS_COND_AXIS_NAME-1 "2-Theta"
*MEAS_COND_AXIS_NAME-2 "Omega"
*MEAS_COND_AXIS_NAME-3 "Z"
*MEAS_COND_AXIS_NAME-4 "2-Theta/Omega"
*MEAS_COND_AXIS_NAME-5 "Theta_s"
*MEAS_COND_AXIS_NAME-6 "Theta_d"
*MEAS_COND_AXIS_NAME-7 "Ts"
*MEAS_COND_AXIS_NAME-8 "CBO selection slit"
*MEAS_COND_AXIS_NAME-9 "M"
*MEAS_COND_AXIS_NAME-10 "Incident parallel slit"
*MEAS_COND_AXIS_NAME-11 "Incident slit"
*MEAS_COND_AXIS_NAME-12 ""
*MEAS_COND_AXIS_NAME-13 "Zs"
*MEAS_COND_AXIS_NAME-14 "Incident monochromator"
*MEAS_COND_AXIS_NAME-15 "Length limiting slit"
*MEAS_COND_AXIS_NAME-16 "Center slit"
*MEAS_COND_AXIS_NAME-17 "Filter"
*MEAS_COND_AXIS_NAME-18 "Receiving slit # 1"
*MEAS_COND_AXIS_NAME-19 "Receiving slit # 2"
*MEAS_COND_AXIS_NAME-20 "Receiving optical device"
*MEAS_COND_AXIS_NAME-21 "Receiving parallel slit"
*MEAS_COND_AXIS_NAME-22 "Alignment receiving slit"
*MEAS_COND_AXIS_NAME-23 ""
*MEAS_COND_AXIS_NAME-24 ""
*MEAS_COND_AXIS_NAME-25 "Zd"
*MEAS_COND_AXIS_NAME-26 "Attenuator"
*MEAS_COND_AXIS_NAME-27 "Diffracted beam monochromator"
*MEAS_COND_AXIS_NAME-28 "Monochromator slit"
*MEAS_COND_AXIS_NAME-29 "Primary beam"
*MEAS_COND_AXIS_NAME-30 "HV"
*MEAS_COND_AXIS_NAME-31 "PHA"
*MEAS_COND_AXIS_NAME_INTERNAL-0 "TwoThetaTheta"
*MEAS_COND_AXIS_NAME_INTERNAL-1 "TwoTheta"
*MEAS_COND_AXIS_NAME_INTERNAL-2 "Omega"
*MEAS_COND_AXIS_NAME_INTERNAL-3 "Z"
*MEAS_COND_AXIS_NAME_INTERNAL-4 "TwoThetaOmega"
*MEAS_COND_AXIS_NAME_INTERNAL-5 "ThetaS"
*MEAS_COND_AXIS_NAME_INTERNAL-6 "ThetaD"
*MEAS_COND_AXIS_NAME_INTERNAL-7 "Ts"
*MEAS_COND_AXIS_NAME_INTERNAL-8 "CBO"
*MEAS_COND_AXIS_NAME_INTERNAL-9 "CBO-M"
*MEAS_COND_AXIS_NAME_INTERNAL-10 "IncidentSollerSlit"
*MEAS_COND_AXIS_NAME_INTERNAL-11 "IncidentSlitBox"
*MEAS_COND_AXIS_NAME_INTERNAL-12 "IncidentSlitBox-_Axis"
*MEAS_COND_AXIS_NAME_INTERNAL-13 "Zs"
*MEAS_COND_AXIS_NAME_INTERNAL-14 "IncidentMonochromator"
*MEAS_COND_AXIS_NAME_INTERNAL-15 "IncidentAxdSlit"
*MEAS_COND_AXIS_NAME_INTERNAL-16 "CenterSlit"
*MEAS_COND_AXIS_NAME_INTERNAL-17 "Filter"
*MEAS_COND_AXIS_NAME_INTERNAL-18 "ReceivingSlitBox1"
*MEAS_COND_AXIS_NAME_INTERNAL-19 "ReceivingSlitBox2"
*MEAS_COND_AXIS_NAME_INTERNAL-20 "ReceivingOptics"
*MEAS_COND_AXIS_NAME_INTERNAL-21 "ReceivingSollerSlit"
*MEAS_COND_AXIS_NAME_INTERNAL-22 "ReceivingAxdSlit"
*MEAS_COND_AXIS_NAME_INTERNAL-23 "ReceivingSlitBox1-_Axis"
*MEAS_COND_AXIS_NAME_INTERNAL-24 "ReceivingSlitBox2-_Axis"
*MEAS_COND_AXIS_NAME_INTERNAL-25 "ReceivingSlitBox2-Zd"
*MEAS_COND_AXIS_NAME_INTERNAL-26 "Attenuator"
*MEAS_COND_AXIS_NAME_INTERNAL-27 "CounterMonochromator"
*MEAS_COND_AXIS_NAME_INTERNAL-28 "CounterSlit"
*MEAS_COND_AXIS_NAME_INTERNAL-29 "IncidentPrimary"
*MEAS_COND_AXIS_NAME_INTERNAL-30 "HV"
*MEAS_COND_AXIS_NAME_INTERNAL-31 "PHA"
*MEAS_COND_AXIS_NAME_MAGICNO-0 "83951616.0000000000"
*MEAS_COND_AXIS_NAME_MAGICNO-1 "268632064.0000000000"
*MEAS_COND_AXIS_NAME_MAGICNO-2 "268500992.0000000000"
*MEAS_COND_AXIS_NAME_MAGICNO-3 "285278208.0000000000"
*MEAS_COND_AXIS_NAME_MAGICNO-4 "83951616.0000000000"
*MEAS_COND_AXIS_NAME_MAGICNO-5 "131072.0000000000"
*MEAS_COND_AXIS_NAME_MAGICNO-6 "131072.0000000000"
*MEAS_COND_AXIS_NAME_MAGICNO-7 "318898176.0000000000"
*MEAS_COND_AXIS_NAME_MAGICNO-8 "20971521.0000000000"
*MEAS_COND_AXIS_NAME_MAGICNO-9 "285343744.0000000000"
*MEAS_COND_AXIS_NAME_MAGICNO-10 "20971521.0000000000"
*MEAS_COND_AXIS_NAME_MAGICNO-11 "22020097.0000000000"
*MEAS_COND_AXIS_NAME_MAGICNO-12 "25165824.0000000000"
*MEAS_COND_AXIS_NAME_MAGICNO-13 "318898176.0000000000"
*MEAS_COND_AXIS_NAME_MAGICNO-14 "1.0000000000"
*MEAS_COND_AXIS_NAME_MAGICNO-15 "20971521.0000000000"
*MEAS_COND_AXIS_NAME_MAGICNO-16 "20971521.0000000000"
*MEAS_COND_AXIS_NAME_MAGICNO-17 "20971521.0000000000"
*MEAS_COND_AXIS_NAME_MAGICNO-18 "23068673.0000000000"
*MEAS_COND_AXIS_NAME_MAGICNO-19 "23068673.0000000000"
*MEAS_COND_AXIS_NAME_MAGICNO-20 "20971521.0000000000"
*MEAS_COND_AXIS_NAME_MAGICNO-21 "20971521.0000000000"
*MEAS_COND_AXIS_NAME_MAGICNO-22 "20971521.0000000000"
*MEAS_COND_AXIS_NAME_MAGICNO-23 "25165824.0000000000"
*MEAS_COND_AXIS_NAME_MAGICNO-24 "25165824.0000000000"
*MEAS_COND_AXIS_NAME_MAGICNO-25 "285343744.0000000000"
*MEAS_COND_AXIS_NAME_MAGICNO-26 "17301505.0000000000"
*MEAS_COND_AXIS_NAME_MAGICNO-27 "20971521.0000000000"
*MEAS_COND_AXIS_NAME_MAGICNO-28 "20971521.0000000000"
*MEAS_COND_AXIS_NAME_MAGICNO-29 "20971521.0000000000"
*MEAS_COND_AXIS_NAME_MAGICNO-30 "0.0000000000"
*MEAS_COND_AXIS_NAME_MAGICNO-31 "0.0000000000"
*MEAS_COND_AXIS_OFFSET-0 "-"
*MEAS_COND_AXIS_OFFSET-1 "0.9820000000"
*MEAS_COND_AXIS_OFFSET-2 "0.3761000000"
*MEAS_COND_AXIS_OFFSET-3 "-"
*MEAS_COND_AXIS_OFFSET-4 "-"
*MEAS_COND_AXIS_OFFSET-5 "0.3761000000"
*MEAS_COND_AXIS_OFFSET-6 "0.6059000000"
*MEAS_COND_AXIS_OFFSET-7 "-"
*MEAS_COND_AXIS_OFFSET-8 "-"
*MEAS_COND_AXIS_OFFSET-9 "-"
*MEAS_COND_AXIS_OFFSET-10 "-"
*MEAS_COND_AXIS_OFFSET-11 "-"
*MEAS_COND_AXIS_OFFSET-12 "-"
*MEAS_COND_AXIS_OFFSET-13 "-"
*MEAS_COND_AXIS_OFFSET-14 "-"
*MEAS_COND_AXIS_OFFSET-15 "-"
*MEAS_COND_AXIS_OFFSET-16 "-"
*MEAS_COND_AXIS_OFFSET-17 "-"
*MEAS_COND_AXIS_OFFSET-18 "-"
*MEAS_COND_AXIS_OFFSET-19 "-"
*MEAS_COND_AXIS_OFFSET-20 "-"
*MEAS_COND_AXIS_OFFSET-21 "-"
*MEAS_COND_AXIS_OFFSET-22 "-"
*MEAS_COND_AXIS_OFFSET-23 "-"
*MEAS_COND_AXIS_OFFSET-24 "-"
*MEAS_COND_AXIS_OFFSET-25 "-"
*MEAS_COND_AXIS_OFFSET-26 "-"
*MEAS_COND_AXIS_OFFSET-27 "-"
*MEAS_COND_AXIS_OFFSET-28 "-"
*MEAS_COND_AXIS_OFFSET-29 "-"
*MEAS_COND_AXIS_OFFSET-30 "-"
*MEAS_COND_AXIS_OFFSET-31 "-"
*MEAS_COND_AXIS_POSITION-0 "2.0000000000"
*MEAS_COND_AXIS_POSITION-1 "2.0000000000"
*MEAS_COND_AXIS_POSITION-2 "1.0000000000"
*MEAS_COND_AXIS_POSITION-3 "-1.9365600000"
*MEAS_COND_AXIS_POSITION-4 "2.0000000000"
*MEAS_COND_AXIS_POSITION-5 "1.0000000000"
*MEAS_COND_AXIS_POSITION-6 "1.0000000000"
*MEAS_COND_AXIS_POSITION-7 "0.2001900000"
*MEAS_COND_AXIS_POSITION-8 "PB"
*MEAS_COND_AXIS_POSITION-9 "0.0000000000"
*MEAS_COND_AXIS_POSITION-10 "Soller_slit_5.0deg"
*MEAS_COND_AXIS_POSITION-11 "0.200mm"
*MEAS_COND_AXIS_POSITION-12 "0.2000000000"
*MEAS_COND_AXIS_POSITION-13 "-1.2596900000"
*MEAS_COND_AXIS_POSITION-14 "0.0000000000"
*MEAS_COND_AXIS_POSITION-15 "10.0mm"
*MEAS_COND_AXIS_POSITION-16 "None"
*MEAS_COND_AXIS_POSITION-17 "None"
*MEAS_COND_AXIS_POSITION-18 "Open"
*MEAS_COND_AXIS_POSITION-19 "Open"
*MEAS_COND_AXIS_POSITION-20 "PSA_0.5deg"
*MEAS_COND_AXIS_POSITION-21 "Soller_slit_5.0deg"
*MEAS_COND_AXIS_POSITION-22 "None"
*MEAS_COND_AXIS_POSITION-23 "20.0000000000"
*MEAS_COND_AXIS_POSITION-24 "20.0000000000"
*MEAS_COND_AXIS_POSITION-25 "0.0000000000"
*MEAS_COND_AXIS_POSITION-26 "Open"
*MEAS_COND_AXIS_POSITION-27 "None"
*MEAS_COND_AXIS_POSITION-28 "None"
*MEAS_COND_AXIS_POSITION-29 "None"
*MEAS_COND_AXIS_POSITION-30 "638.0000000000"
*MEAS_COND_AXIS_POSITION-31 "572.5000000000"
*MEAS_COND_AXIS_UNIT-0 "deg"
*MEAS_COND_AXIS_UNIT-1 "deg"
*MEAS_COND_AXIS_UNIT-2 "deg"
*MEAS_COND_AXIS_UNIT-3 "mm"
*MEAS_COND_AXIS_UNIT-4 "deg"
*MEAS_COND_AXIS_UNIT-5 "deg"
*MEAS_COND_AXIS_UNIT-6 "deg"
*MEAS_COND_AXIS_UNIT-7 "mm"
*MEAS_COND_AXIS_UNIT-8 ""
*MEAS_COND_AXIS_UNIT-9 "pulse"
*MEAS_COND_AXIS_UNIT-10 ""
*MEAS_COND_AXIS_UNIT-11 ""
*MEAS_COND_AXIS_UNIT-12 "mm"
*MEAS_COND_AXIS_UNIT-13 "mm"
*MEAS_COND_AXIS_UNIT-14 ""
*MEAS_COND_AXIS_UNIT-15 ""
*MEAS_COND_AXIS_UNIT-16 ""
*MEAS_COND_AXIS_UNIT-17 ""
*MEAS_COND_AXIS_UNIT-18 ""
*MEAS_COND_AXIS_UNIT-19 ""
*MEAS_COND_AXIS_UNIT-20 ""
*MEAS_COND_AXIS_UNIT-21 ""
*MEAS_COND_AXIS_UNIT-22 ""
*MEAS_COND_AXIS_UNIT-23 "mm"
*MEAS_COND_AXIS_UNIT-24 "mm"
*MEAS_COND_AXIS_UNIT-25 "mm"
*MEAS_COND_AXIS_UNIT-26 ""
*MEAS_COND_AXIS_UNIT-27 ""
*MEAS_COND_AXIS_UNIT-28 ""
*MEAS_COND_AXIS_UNIT-29 ""
*MEAS_COND_AXIS_UNIT-30 "V"
*MEAS_COND_AXIS_UNIT-31 "mV"
*MEAS_COND_COUNTER_CNTLOSS_CORR "1.0000000000"
*MEAS_COND_COUNTER_PHABASE "572.5000000000"
*MEAS_COND_COUNTER_PHAWINDOW "831.2500000000"
*MEAS_COND_COUNTER_PHA_UNIT "mV"
*MEAS_COND_COUNTER_TAUDIFF "0.1945640000"
*MEAS_COND_COUNTER_TAUINT "0.6497890000"
*MEAS_COND_IRRADIATION_MODE "OFF"
*MEAS_COND_IRRADIATION_WIDTH ""
*MEAS_COND_OPT_ATTR "Medium resolution parallel beam/PSA"
*MEAS_COND_OPT_NAME "@Medium resolution PB/PSA"
*MEAS_COND_UNSYMMETRIC_MODE "OFF"
*MEAS_COND_XG_CURRENT "44.0000000000"
*MEAS_COND_XG_VOLTAGE "40.0000000000"
*MEAS_COND_XG_WAVE_TYPE "Ka"
*MEAS_DATA_COUNT "1401.0000000000"
*MEAS_SCAN_AXIS_X "2-Theta"
*MEAS_SCAN_AXIS_X_INTERNAL "TwoTheta"
*MEAS_SCAN_END_TIME "11/01/12 14:48:07"
*MEAS_SCAN_MODE "CONTINUOUS"
*MEAS_SCAN_MONITOR "0"
*MEAS_SCAN_RESOLUTION_X "0.0001"
*MEAS_SCAN_SPEED "0.2500"
*MEAS_SCAN_SPEED_UNIT "deg/min"
*MEAS_SCAN_START "2.0000000000"
*MEAS_SCAN_START_TIME "11/01/12 12:55:51"
*MEAS_SCAN_STEP "0.0200000000"
*MEAS_SCAN_STOP "30.0000000000"
*MEAS_SCAN_UNIT_X "deg"
*MEAS_SCAN_UNIT_Y "counts"
*RAS_HEADER_END
*RAS_INT_START
2.0000 7994.0000 1.0000
2.0200 7788.0000 1.0000
2.0400 7984.0000 1.0000
2.0600 7799.0000 1.0000
2.0800 7694.0000 1.0000
2.1000 7693.0000 1.0000
2.1200 7586.0000 1.0000
2.1400 7547.0000 1.0000
2.1600 7345.0000 1.0000
2.1800 7392.0000 1.0000
2.2000 7463.0000 1.0000
2.2200 7191.0000 1.0000
2.2400 7102.0000 1.0000
2.2600 7028.0000 1.0000
2.2800 7047.0000 1.0000
2.3000 7029.0000 1.0000
2.3200 7094.0000 1.0000
2.3400 6931.0000 1.0000
2.3600 6936.0000 1.0000
2.3800 6932.0000 1.0000
2.4000 6976.0000 1.0000
2.4200 6982.0000 1.0000
2.4400 6964.0000 1.0000
2.4600 6947.0000 1.0000
2.4800 6935.0000 1.0000
2.5000 6923.0000 1.0000
2.5200 6935.0000 1.0000
2.5400 7118.0000 1.0000
2.5600 7266.0000 1.0000
2.5800 7252.0000 1.0000
2.6000 7579.0000 1.0000
2.6200 7707.0000 1.0000
2.6400 8174.0000 1.0000
2.6600 8861.0000 1.0000
2.6800 9727.0000 1.0000
2.7000 11196.0000 1.0000
2.7200 12904.0000 1.0000
2.7400 14263.0000 1.0000
2.7600 15778.0000 1.0000
2.7800 17724.0000 1.0000
2.8000 18997.0000 1.0000
2.8200 20410.0000 1.0000
2.8400 21745.0000 1.0000
2.8600 22775.0000 1.0000
2.8800 23601.0000 1.0000
2.9000 24208.0000 1.0000
2.9200 24308.0000 1.0000
2.9400 24240.0000 1.0000
2.9600 23710.0000 1.0000
2.9800 22702.0000 1.0000
3.0000 21657.0000 1.0000
3.0200 20433.0000 1.0000
3.0400 18808.0000 1.0000
3.0600 17574.0000 1.0000
3.0800 15958.0000 1.0000
3.1000 14539.0000 1.0000
3.1200 12901.0000 1.0000
3.1400 11450.0000 1.0000
3.1600 10118.0000 1.0000
3.1800 9141.0000 1.0000
3.2000 8140.0000 1.0000
3.2200 7474.0000 1.0000
3.2400 7120.0000 1.0000
3.2600 6749.0000 1.0000
3.2800 6799.0000 1.0000
3.3000 6536.0000 1.0000
3.3200 6556.0000 1.0000
3.3400 6365.0000 1.0000
3.3600 6277.0000 1.0000
3.3800 6190.0000 1.0000
3.4000 6228.0000 1.0000
3.4200 6145.0000 1.0000
3.4400 6146.0000 1.0000
3.4600 6219.0000 1.0000
3.4800 6255.0000 1.0000
3.5000 6282.0000 1.0000
3.5200 6221.0000 1.0000
3.5400 6071.0000 1.0000
3.5600 6010.0000 1.0000
3.5800 6085.0000 1.0000
3.6000 6096.0000 1.0000
3.6200 6106.0000 1.0000
3.6400 6155.0000 1.0000
3.6600 6002.0000 1.0000
3.6800 5963.0000 1.0000
3.7000 6110.0000 1.0000
3.7200 6017.0000 1.0000
3.7400 6119.0000 1.0000
3.7600 5995.0000 1.0000
3.7800 5976.0000 1.0000
3.8000 6122.0000 1.0000
3.8200 5964.0000 1.0000
3.8400 6095.0000 1.0000
3.8600 5937.0000 1.0000
3.8800 6001.0000 1.0000
3.9000 5960.0000 1.0000
3.9200 5829.0000 1.0000
3.9400 5862.0000 1.0000
3.9600 6074.0000 1.0000
3.9800 5980.0000 1.0000
4.0000 6010.0000 1.0000
4.0200 5823.0000 1.0000
4.0400 5901.0000 1.0000
4.0600 5834.0000 1.0000
4.0800 5870.0000 1.0000
4.1000 6037.0000 1.0000
4.1200 5790.0000 1.0000
4.1400 5928.0000 1.0000
4.1600 5627.0000 1.0000
4.1800 5974.0000 1.0000
4.2000 5877.0000 1.0000
4.2200 5944.0000 1.0000
4.2400 5780.0000 1.0000
4.2600 5805.0000 1.0000
4.2800 5835.0000 1.0000
4.3000 5967.0000 1.0000
4.3200 5895.0000 1.0000
4.3400 5912.0000 1.0000
4.3600 5900.0000 1.0000
4.3800 5655.0000 1.0000
4.4000 5773.0000 1.0000
4.4200 5809.0000 1.0000
4.4400 5894.0000 1.0000
4.4600 5830.0000 1.0000
4.4800 5821.0000 1.0000
4.5000 5865.0000 1.0000
4.5200 5758.0000 1.0000
4.5400 5769.0000 1.0000
4.5600 5832.0000 1.0000
4.5800 5816.0000 1.0000
4.6000 5794.0000 1.0000
4.6200 5789.0000 1.0000
4.6400 5656.0000 1.0000
4.6600 5752.0000 1.0000
4.6800 5753.0000 1.0000
4.7000 5953.0000 1.0000
4.7200 5624.0000 1.0000
4.7400 5716.0000 1.0000
4.7600 5718.0000 1.0000
4.7800 5780.0000 1.0000
4.8000 5707.0000 1.0000
4.8200 5567.0000 1.0000
4.8400 5787.0000 1.0000
4.8600 5723.0000 1.0000
4.8800 5708.0000 1.0000
4.9000 5647.0000 1.0000
4.9200 5594.0000 1.0000
4.9400 5572.0000 1.0000
4.9600 5545.0000 1.0000
4.9800 5568.0000 1.0000
5.0000 5634.0000 1.0000
5.0200 5632.0000 1.0000
5.0400 5681.0000 1.0000
5.0600 5668.0000 1.0000
5.0800 5565.0000 1.0000
5.1000 5634.0000 1.0000
5.1200 5489.0000 1.0000
5.1400 5666.0000 1.0000
5.1600 5538.0000 1.0000
5.1800 5692.0000 1.0000
5.2000 5497.0000 1.0000
5.2200 5628.0000 1.0000
5.2400 5574.0000 1.0000
5.2600 5549.0000 1.0000
5.2800 5402.0000 1.0000
5.3000 5626.0000 1.0000
5.3200 5510.0000 1.0000
5.3400 5564.0000 1.0000
5.3600 5409.0000 1.0000
5.3800 5600.0000 1.0000
5.4000 5356.0000 1.0000
5.4200 5384.0000 1.0000
5.4400 5522.0000 1.0000
5.4600 5445.0000 1.0000
5.4800 5502.0000 1.0000
5.5000 5405.0000 1.0000
5.5200 5558.0000 1.0000
5.5400 5460.0000 1.0000
5.5600 5415.0000 1.0000
5.5800 5377.0000 1.0000
5.6000 5355.0000 1.0000
5.6200 5322.0000 1.0000
5.6400 5530.0000 1.0000
5.6600 5375.0000 1.0000
5.6800 5461.0000 1.0000
5.7000 5430.0000 1.0000
5.7200 5447.0000 1.0000
5.7400 5377.0000 1.0000
5.7600 5456.0000 1.0000
5.7800 5418.0000 1.0000
5.8000 5366.0000 1.0000
5.8200 5260.0000 1.0000
5.8400 5341.0000 1.0000
5.8600 5215.0000 1.0000
5.8800 5249.0000 1.0000
5.9000 5350.0000 1.0000
5.9200 5370.0000 1.0000
5.9400 5378.0000 1.0000
5.9600 5394.0000 1.0000
5.9800 5440.0000 1.0000
6.0000 5467.0000 1.0000
6.0200 5494.0000 1.0000
6.0400 5452.0000 1.0000
6.0600 5626.0000 1.0000
6.0800 5680.0000 1.0000
6.1000 5658.0000 1.0000
6.1200 5662.0000 1.0000
6.1400 5762.0000 1.0000
6.1600 5760.0000 1.0000
6.1800 5885.0000 1.0000
6.2000 5847.0000 1.0000
6.2200 6090.0000 1.0000
6.2400 6185.0000 1.0000
6.2600 6381.0000 1.0000
6.2800 6381.0000 1.0000
6.3000 6633.0000 1.0000
6.3200 6845.0000 1.0000
6.3400 7065.0000 1.0000
6.3600 7334.0000 1.0000
6.3800 7668.0000 1.0000
6.4000 8118.0000 1.0000
6.4200 8853.0000 1.0000
6.4400 9553.0000 1.0000
6.4600 10336.0000 1.0000
6.4800 11480.0000 1.0000
6.5000 13082.0000 1.0000
6.5200 15169.0000 1.0000
6.5400 17457.0000 1.0000
6.5600 21368.0000 1.0000
6.5800 26472.0000 1.0000
6.6000 32511.0000 1.0000
6.6200 41145.0000 1.0000
6.6400 51746.0000 1.0000
6.6600 64094.0000 1.0000
6.6800 76516.0000 1.0000
6.7000 90286.0000 1.0000
6.7200 103980.0000 1.0000
6.7400 117249.0000 1.0000
6.7600 129747.0000 1.0000
6.7800 142090.0000 1.0000
6.8000 152759.0000 1.0000
6.8200 162335.0000 1.0000
6.8400 168226.0000 1.0000
6.8600 171952.0000 1.0000
6.8800 173128.0000 1.0000
6.9000 171842.0000 1.0000
6.9200 168552.0000 1.0000
6.9400 162261.0000 1.0000
6.9600 153958.0000 1.0000
6.9800 143623.0000 1.0000
7.0000 133506.0000 1.0000
7.0200 120871.0000 1.0000
7.0400 108227.0000 1.0000
7.0600 95025.0000 1.0000
7.0800 82365.0000 1.0000
7.1000 70334.0000 1.0000
7.1200 59121.0000 1.0000
7.1400 50138.0000 1.0000
7.1600 42222.0000 1.0000
7.1800 35939.0000 1.0000
7.2000 30502.0000 1.0000
7.2200 25533.0000 1.0000
7.2400 22273.0000 1.0000
7.2600 18941.0000 1.0000
7.2800 16075.0000 1.0000
7.3000 14081.0000 1.0000
7.3200 12069.0000 1.0000
7.3400 10848.0000 1.0000
7.3600 9781.0000 1.0000
7.3800 8603.0000 1.0000
7.4000 7670.0000 1.0000
7.4200 7184.0000 1.0000
7.4400 6813.0000 1.0000
7.4600 6115.0000 1.0000
7.4800 5909.0000 1.0000
7.5000 5642.0000 1.0000
7.5200 5226.0000 1.0000
7.5400 4950.0000 1.0000
7.5600 5010.0000 1.0000
7.5800 4757.0000 1.0000
7.6000 4443.0000 1.0000
7.6200 4517.0000 1.0000
7.6400 4445.0000 1.0000
7.6600 4232.0000 1.0000
7.6800 4424.0000 1.0000
7.7000 4200.0000 1.0000
7.7200 4264.0000 1.0000
7.7400 4093.0000 1.0000
7.7600 4161.0000 1.0000
7.7800 4020.0000 1.0000
7.8000 3970.0000 1.0000
7.8200 3975.0000 1.0000
7.8400 4005.0000 1.0000
7.8600 3800.0000 1.0000
7.8800 3970.0000 1.0000
7.9000 3949.0000 1.0000
7.9200 3947.0000 1.0000
7.9400 3898.0000 1.0000
7.9600 3995.0000 1.0000
7.9800 3783.0000 1.0000
8.0000 3771.0000 1.0000
8.0200 3766.0000 1.0000
8.0400 3729.0000 1.0000
8.0600 3672.0000 1.0000
8.0800 3717.0000 1.0000
8.1000 3685.0000 1.0000
8.1200 3735.0000 1.0000
8.1400 3587.0000 1.0000
8.1600 3708.0000 1.0000
8.1800 3633.0000 1.0000
8.2000 3784.0000 1.0000
8.2200 3594.0000 1.0000
8.2400 3691.0000 1.0000
8.2600 3636.0000 1.0000
8.2800 3606.0000 1.0000
8.3000 3572.0000 1.0000
8.3200 3644.0000 1.0000
8.3400 3542.0000 1.0000
8.3600 3528.0000 1.0000
8.3800 3622.0000 1.0000
8.4000 3633.0000 1.0000
8.4200 3556.0000 1.0000
8.4400 3561.0000 1.0000
8.4600 3437.0000 1.0000
8.4800 3524.0000 1.0000
8.5000 3527.0000 1.0000
8.5200 3605.0000 1.0000
8.5400 3522.0000 1.0000
8.5600 3350.0000 1.0000
8.5800 3496.0000 1.0000
8.6000 3472.0000 1.0000
8.6200 3451.0000 1.0000
8.6400 3450.0000 1.0000
8.6600 3544.0000 1.0000
8.6800 3431.0000 1.0000
8.7000 3383.0000 1.0000
8.7200 3413.0000 1.0000
8.7400 3556.0000 1.0000
8.7600 3493.0000 1.0000
8.7800 3395.0000 1.0000
8.8000 3428.0000 1.0000
8.8200 3437.0000 1.0000
8.8400 3353.0000 1.0000
8.8600 3383.0000 1.0000
8.8800 3390.0000 1.0000
8.9000 3342.0000 1.0000
8.9200 3259.0000 1.0000
8.9400 3392.0000 1.0000
8.9600 3330.0000 1.0000
8.9800 3256.0000 1.0000
9.0000 3237.0000 1.0000
9.0200 3306.0000 1.0000
9.0400 3215.0000 1.0000
9.0600 3330.0000 1.0000
9.0800 3252.0000 1.0000
9.1000 3276.0000 1.0000
9.1200 3319.0000 1.0000
9.1400 3179.0000 1.0000
9.1600 3243.0000 1.0000
9.1800 3257.0000 1.0000
9.2000 3247.0000 1.0000
9.2200 3263.0000 1.0000
9.2400 3228.0000 1.0000
9.2600 3175.0000 1.0000
9.2800 3219.0000 1.0000
9.3000 3289.0000 1.0000
9.3200 3083.0000 1.0000
9.3400 3126.0000 1.0000
9.3600 3136.0000 1.0000
9.3800 3213.0000 1.0000
9.4000 3112.0000 1.0000
9.4200 3220.0000 1.0000
9.4400 3135.0000 1.0000
9.4600 3091.0000 1.0000
9.4800 3067.0000 1.0000
9.5000 3155.0000 1.0000
9.5200 3121.0000 1.0000
9.5400 3124.0000 1.0000
9.5600 3099.0000 1.0000
9.5800 3021.0000 1.0000
9.6000 3155.0000 1.0000
9.6200 3070.0000 1.0000
9.6400 3077.0000 1.0000
9.6600 3067.0000 1.0000
9.6800 3052.0000 1.0000
9.7000 3033.0000 1.0000
9.7200 3081.0000 1.0000
9.7400 3051.0000 1.0000
9.7600 3112.0000 1.0000
9.7800 3073.0000 1.0000
9.8000 3031.0000 1.0000
9.8200 3031.0000 1.0000
9.8400 3123.0000 1.0000
9.8600 3091.0000 1.0000
9.8800 3026.0000 1.0000
9.9000 3001.0000 1.0000
9.9200 2955.0000 1.0000
9.9400 3020.0000 1.0000
9.9600 2980.0000 1.0000
9.9800 3073.0000 1.0000
10.0000 2955.0000 1.0000
10.0200 3022.0000 1.0000
10.0400 3000.0000 1.0000
10.0600 3070.0000 1.0000
10.0800 2919.0000 1.0000
10.1000 2867.0000 1.0000
10.1200 2945.0000 1.0000
10.1400 2868.0000 1.0000
10.1600 2914.0000 1.0000
10.1800 2964.0000 1.0000
10.2000 2855.0000 1.0000
10.2200 2950.0000 1.0000
10.2400 2864.0000 1.0000
10.2600 2952.0000 1.0000
10.2800 2886.0000 1.0000
10.3000 2871.0000 1.0000
10.3200 2824.0000 1.0000
10.3400 2895.0000 1.0000
10.3600 2915.0000 1.0000
10.3800 2802.0000 1.0000
10.4000 2898.0000 1.0000
10.4200 2776.0000 1.0000
10.4400 2830.0000 1.0000
10.4600 2879.0000 1.0000
10.4800 2893.0000 1.0000
10.5000 2802.0000 1.0000
10.5200 2825.0000 1.0000
10.5400 2846.0000 1.0000
10.5600 2861.0000 1.0000
10.5800 2868.0000 1.0000
10.6000 2816.0000 1.0000
10.6200 2760.0000 1.0000
10.6400 2793.0000 1.0000
10.6600 2806.0000 1.0000
10.6800 2776.0000 1.0000
10.7000 2708.0000 1.0000
10.7200 2835.0000 1.0000
10.7400 2844.0000 1.0000
10.7600 2791.0000 1.0000
10.7800 2744.0000 1.0000
10.8000 2822.0000 1.0000
10.8200 2711.0000 1.0000
10.8400 2726.0000 1.0000
10.8600 2705.0000 1.0000
10.8800 2689.0000 1.0000
10.9000 2882.0000 1.0000
10.9200 2675.0000 1.0000
10.9400 2724.0000 1.0000
10.9600 2738.0000 1.0000
10.9800 2628.0000 1.0000
11.0000 2686.0000 1.0000
11.0200 2700.0000 1.0000
11.0400 2689.0000 1.0000
11.0600 2671.0000 1.0000
11.0800 2707.0000 1.0000
11.1000 2680.0000 1.0000
11.1200 2651.0000 1.0000
11.1400 2637.0000 1.0000
11.1600 2634.0000 1.0000
11.1800 2727.0000 1.0000
11.2000 2650.0000 1.0000
11.2200 2707.0000 1.0000
11.2400 2665.0000 1.0000
11.2600 2742.0000 1.0000
11.2800 2637.0000 1.0000
11.3000 2629.0000 1.0000
11.3200 2576.0000 1.0000
11.3400 2582.0000 1.0000
11.3600 2640.0000 1.0000
11.3800 2576.0000 1.0000
11.4000 2753.0000 1.0000
11.4200 2617.0000 1.0000
11.4400 2657.0000 1.0000
11.4600 2660.0000 1.0000
11.4800 2585.0000 1.0000
11.5000 2592.0000 1.0000
11.5200 2543.0000 1.0000
11.5400 2582.0000 1.0000
11.5600 2613.0000 1.0000
11.5800 2530.0000 1.0000
11.6000 2573.0000 1.0000
11.6200 2560.0000 1.0000
11.6400 2663.0000 1.0000
11.6600 2608.0000 1.0000
11.6800 2499.0000 1.0000
11.7000 2461.0000 1.0000
11.7200 2498.0000 1.0000
11.7400 2579.0000 1.0000
11.7600 2597.0000 1.0000
11.7800 2541.0000 1.0000
11.8000 2593.0000 1.0000
11.8200 2549.0000 1.0000
11.8400 2530.0000 1.0000
11.8600 2560.0000 1.0000
11.8800 2497.0000 1.0000
11.9000 2544.0000 1.0000
11.9200 2516.0000 1.0000
11.9400 2454.0000 1.0000
11.9600 2599.0000 1.0000
11.9800 2542.0000 1.0000
12.0000 2424.0000 1.0000
12.0200 2532.0000 1.0000
12.0400 2481.0000 1.0000
12.0600 2541.0000 1.0000
12.0800 2541.0000 1.0000
12.1000 2526.0000 1.0000
12.1200 2439.0000 1.0000
12.1400 2519.0000 1.0000
12.1600 2538.0000 1.0000
12.1800 2398.0000 1.0000
12.2000 2449.0000 1.0000
12.2200 2422.0000 1.0000
12.2400 2329.0000 1.0000
12.2600 2449.0000 1.0000
12.2800 2412.0000 1.0000
12.3000 2465.0000 1.0000
12.3200 2425.0000 1.0000
12.3400 2360.0000 1.0000
12.3600 2415.0000 1.0000
12.3800 2437.0000 1.0000
12.4000 2487.0000 1.0000
12.4200 2420.0000 1.0000
12.4400 2341.0000 1.0000
12.4600 2536.0000 1.0000
12.4800 2422.0000 1.0000
12.5000 2430.0000 1.0000
12.5200 2508.0000 1.0000
12.5400 2471.0000 1.0000
12.5600 2345.0000 1.0000
12.5800 2341.0000 1.0000
12.6000 2440.0000 1.0000
12.6200 2376.0000 1.0000
12.6400 2395.0000 1.0000
12.6600 2310.0000 1.0000
12.6800 2407.0000 1.0000
12.7000 2373.0000 1.0000
12.7200 2329.0000 1.0000
12.7400 2363.0000 1.0000
12.7600 2370.0000 1.0000
12.7800 2389.0000 1.0000
12.8000 2286.0000 1.0000
12.8200 2402.0000 1.0000
12.8400 2353.0000 1.0000
12.8600 2338.0000 1.0000
12.8800 2381.0000 1.0000
12.9000 2381.0000 1.0000
12.9200 2308.0000 1.0000
12.9400 2323.0000 1.0000
12.9600 2367.0000 1.0000
12.9800 2372.0000 1.0000
13.0000 2351.0000 1.0000
13.0200 2347.0000 1.0000
13.0400 2306.0000 1.0000
13.0600 2365.0000 1.0000
13.0800 2403.0000 1.0000
13.1000 2336.0000 1.0000
13.1200 2261.0000 1.0000
13.1400 2309.0000 1.0000
13.1600 2313.0000 1.0000
13.1800 2322.0000 1.0000
13.2000 2307.0000 1.0000
13.2200 2382.0000 1.0000
13.2400 2361.0000 1.0000
13.2600 2278.0000 1.0000
13.2800 2414.0000 1.0000
13.3000 2403.0000 1.0000
13.3200 2429.0000 1.0000
13.3400 2340.0000 1.0000
13.3600 2454.0000 1.0000
13.3800 2253.0000 1.0000
13.4000 2414.0000 1.0000
13.4200 2319.0000 1.0000
13.4400 2365.0000 1.0000
13.4600 2454.0000 1.0000
13.4800 2360.0000 1.0000
13.5000 2389.0000 1.0000
13.5200 2378.0000 1.0000
13.5400 2483.0000 1.0000
13.5600 2416.0000 1.0000
13.5800 2492.0000 1.0000
13.6000 2576.0000 1.0000
13.6200 2516.0000 1.0000
13.6400 2524.0000 1.0000
13.6600 2482.0000 1.0000
13.6800 2492.0000 1.0000
13.7000 2525.0000 1.0000
13.7200 2583.0000 1.0000
13.7400 2478.0000 1.0000
13.7600 2462.0000 1.0000
13.7800 2482.0000 1.0000
13.8000 2485.0000 1.0000
13.8200 2470.0000 1.0000
13.8400 2474.0000 1.0000
13.8600 2423.0000 1.0000
13.8800 2392.0000 1.0000
13.9000 2370.0000 1.0000
13.9200 2375.0000 1.0000
13.9400 2350.0000 1.0000
13.9600 2422.0000 1.0000
13.9800 2391.0000 1.0000
14.0000 2300.0000 1.0000
14.0200 2401.0000 1.0000
14.0400 2301.0000 1.0000
14.0600 2260.0000 1.0000
14.0800 2387.0000 1.0000
14.1000 2219.0000 1.0000
14.1200 2225.0000 1.0000
14.1400 2238.0000 1.0000
14.1600 2254.0000 1.0000
14.1800 2266.0000 1.0000
14.2000 2177.0000 1.0000
14.2200 2200.0000 1.0000
14.2400 2178.0000 1.0000
14.2600 2242.0000 1.0000
14.2800 2183.0000 1.0000
14.3000 2165.0000 1.0000
14.3200 2164.0000 1.0000
14.3400 2209.0000 1.0000
14.3600 2092.0000 1.0000
14.3800 2075.0000 1.0000
14.4000 2265.0000 1.0000
14.4200 2133.0000 1.0000
14.4400 2126.0000 1.0000
14.4600 2177.0000 1.0000
14.4800 2101.0000 1.0000
14.5000 2174.0000 1.0000
14.5200 2065.0000 1.0000
14.5400 2101.0000 1.0000
14.5600 2175.0000 1.0000
14.5800 2068.0000 1.0000
14.6000 2112.0000 1.0000
14.6200 2187.0000 1.0000
14.6400 2073.0000 1.0000
14.6600 2135.0000 1.0000
14.6800 2067.0000 1.0000
14.7000 2079.0000 1.0000
14.7200 2112.0000 1.0000
14.7400 2077.0000 1.0000
14.7600 2054.0000 1.0000
14.7800 2053.0000 1.0000
14.8000 2083.0000 1.0000
14.8200 2126.0000 1.0000
14.8400 2014.0000 1.0000
14.8600 1952.0000 1.0000
14.8800 2109.0000 1.0000
14.9000 2013.0000 1.0000
14.9200 1991.0000 1.0000
14.9400 2066.0000 1.0000
14.9600 2082.0000 1.0000
14.9800 2092.0000 1.0000
15.0000 2046.0000 1.0000
15.0200 2002.0000 1.0000
15.0400 2008.0000 1.0000
15.0600 2009.0000 1.0000
15.0800 2023.0000 1.0000
15.1000 1945.0000 1.0000
15.1200 1990.0000 1.0000
15.1400 1981.0000 1.0000
15.1600 1976.0000 1.0000
15.1800 2002.0000 1.0000
15.2000 1940.0000 1.0000
15.2200 2005.0000 1.0000
15.2400 1997.0000 1.0000
15.2600 2034.0000 1.0000
15.2800 1948.0000 1.0000
15.3000 1973.0000 1.0000
15.3200 2000.0000 1.0000
15.3400 1873.0000 1.0000
15.3600 2039.0000 1.0000
15.3800 1942.0000 1.0000
15.4000 1974.0000 1.0000
15.4200 1967.0000 1.0000
15.4400 1919.0000 1.0000
15.4600 1921.0000 1.0000
15.4800 1922.0000 1.0000
15.5000 1955.0000 1.0000
15.5200 1949.0000 1.0000
15.5400 1882.0000 1.0000
15.5600 1935.0000 1.0000
15.5800 1904.0000 1.0000
15.6000 1948.0000 1.0000
15.6200 1886.0000 1.0000
15.6400 1914.0000 1.0000
15.6600 1954.0000 1.0000
15.6800 1860.0000 1.0000
15.7000 1817.0000 1.0000
15.7200 1987.0000 1.0000
15.7400 1921.0000 1.0000
15.7600 1882.0000 1.0000
15.7800 1929.0000 1.0000
15.8000 1905.0000 1.0000
15.8200 1892.0000 1.0000
15.8400 1841.0000 1.0000
15.8600 1935.0000 1.0000
15.8800 1876.0000 1.0000
15.9000 1884.0000 1.0000
15.9200 1965.0000 1.0000
15.9400 1879.0000 1.0000
15.9600 1865.0000 1.0000
15.9800 1897.0000 1.0000
16.0000 1761.0000 1.0000
16.0200 1850.0000 1.0000
16.0400 1936.0000 1.0000
16.0600 1910.0000 1.0000
16.0800 1826.0000 1.0000
16.1000 1923.0000 1.0000
16.1200 1908.0000 1.0000
16.1400 1864.0000 1.0000
16.1600 1819.0000 1.0000
16.1800 1834.0000 1.0000
16.2000 1869.0000 1.0000
16.2200 1964.0000 1.0000
16.2400 1878.0000 1.0000
16.2600 1974.0000 1.0000
16.2800 1867.0000 1.0000
16.3000 1818.0000 1.0000
16.3200 1865.0000 1.0000
16.3400 1811.0000 1.0000
16.3600 1811.0000 1.0000
16.3800 1782.0000 1.0000
16.4000 1789.0000 1.0000
16.4200 1823.0000 1.0000
16.4400 1847.0000 1.0000
16.4600 1860.0000 1.0000
16.4800 1833.0000 1.0000
16.5000 1818.0000 1.0000
16.5200 1822.0000 1.0000
16.5400 1813.0000 1.0000
16.5600 1842.0000 1.0000
16.5800 1774.0000 1.0000
16.6000 1847.0000 1.0000
16.6200 1840.0000 1.0000
16.6400 1805.0000 1.0000
16.6600 1749.0000 1.0000
16.6800 1758.0000 1.0000
16.7000 1750.0000 1.0000
16.7200 1688.0000 1.0000
16.7400 1751.0000 1.0000
16.7600 1837.0000 1.0000
16.7800 1795.0000 1.0000
16.8000 1801.0000 1.0000
16.8200 1787.0000 1.0000
16.8400 1716.0000 1.0000
16.8600 1775.0000 1.0000
16.8800 1852.0000 1.0000
16.9000 1787.0000 1.0000
16.9200 1745.0000 1.0000
16.9400 1732.0000 1.0000
16.9600 1774.0000 1.0000
16.9800 1750.0000 1.0000
17.0000 1781.0000 1.0000
17.0200 1732.0000 1.0000
17.0400 1750.0000 1.0000
17.0600 1719.0000 1.0000
17.0800 1754.0000 1.0000
17.1000 1812.0000 1.0000
17.1200 1756.0000 1.0000
17.1400 1827.0000 1.0000
17.1600 1783.0000 1.0000
17.1800 1717.0000 1.0000
17.2000 1628.0000 1.0000
17.2200 1783.0000 1.0000
17.2400 1759.0000 1.0000
17.2600 1740.0000 1.0000
17.2800 1705.0000 1.0000
17.3000 1668.0000 1.0000
17.3200 1669.0000 1.0000
17.3400 1789.0000 1.0000
17.3600 1713.0000 1.0000
17.3800 1691.0000 1.0000
17.4000 1640.0000 1.0000
17.4200 1757.0000 1.0000
17.4400 1718.0000 1.0000
17.4600 1709.0000 1.0000
17.4800 1751.0000 1.0000
17.5000 1762.0000 1.0000
17.5200 1641.0000 1.0000
17.5400 1755.0000 1.0000
17.5600 1699.0000 1.0000
17.5800 1750.0000 1.0000
17.6000 1710.0000 1.0000
17.6200 1782.0000 1.0000
17.6400 1713.0000 1.0000
17.6600 1690.0000 1.0000
17.6800 1713.0000 1.0000
17.7000 1685.0000 1.0000
17.7200 1712.0000 1.0000
17.7400 1704.0000 1.0000
17.7600 1707.0000 1.0000
17.7800 1716.0000 1.0000
17.8000 1704.0000 1.0000
17.8200 1825.0000 1.0000
17.8400 1634.0000 1.0000
17.8600 1693.0000 1.0000
17.8800 1680.0000 1.0000
17.9000 1652.0000 1.0000
17.9200 1681.0000 1.0000
17.9400 1701.0000 1.0000
17.9600 1653.0000 1.0000
17.9800 1625.0000 1.0000
18.0000 1619.0000 1.0000
18.0200 1672.0000 1.0000
18.0400 1621.0000 1.0000
18.0600 1676.0000 1.0000
18.0800 1684.0000 1.0000
18.1000 1641.0000 1.0000
18.1200 1720.0000 1.0000
18.1400 1687.0000 1.0000
18.1600 1650.0000 1.0000
18.1800 1617.0000 1.0000
18.2000 1647.0000 1.0000
18.2200 1695.0000 1.0000
18.2400 1690.0000 1.0000
18.2600 1642.0000 1.0000
18.2800 1695.0000 1.0000
18.3000 1625.0000 1.0000
18.3200 1715.0000 1.0000
18.3400 1649.0000 1.0000
18.3600 1661.0000 1.0000
18.3800 1661.0000 1.0000
18.4000 1606.0000 1.0000
18.4200 1648.0000 1.0000
18.4400 1665.0000 1.0000
18.4600 1626.0000 1.0000
18.4800 1678.0000 1.0000
18.5000 1671.0000 1.0000
18.5200 1545.0000 1.0000
18.5400 1705.0000 1.0000
18.5600 1591.0000 1.0000
18.5800 1647.0000 1.0000
18.6000 1569.0000 1.0000
18.6200 1596.0000 1.0000
18.6400 1629.0000 1.0000
18.6600 1667.0000 1.0000
18.6800 1612.0000 1.0000
18.7000 1632.0000 1.0000
18.7200 1594.0000 1.0000
18.7400 1636.0000 1.0000
18.7600 1604.0000 1.0000
18.7800 1565.0000 1.0000
18.8000 1601.0000 1.0000
18.8200 1554.0000 1.0000
18.8400 1639.0000 1.0000
18.8600 1554.0000 1.0000
18.8800 1624.0000 1.0000
18.9000 1636.0000 1.0000
18.9200 1607.0000 1.0000
18.9400 1611.0000 1.0000
18.9600 1599.0000 1.0000
18.9800 1545.0000 1.0000
19.0000 1635.0000 1.0000
19.0200 1575.0000 1.0000
19.0400 1587.0000 1.0000
19.0600 1624.0000 1.0000
19.0800 1594.0000 1.0000
19.1000 1598.0000 1.0000
19.1200 1562.0000 1.0000
19.1400 1538.0000 1.0000
19.1600 1545.0000 1.0000
19.1800 1552.0000 1.0000
19.2000 1524.0000 1.0000
19.2200 1601.0000 1.0000
19.2400 1613.0000 1.0000
19.2600 1600.0000 1.0000
19.2800 1654.0000 1.0000
19.3000 1552.0000 1.0000
19.3200 1604.0000 1.0000
19.3400 1581.0000 1.0000
19.3600 1642.0000 1.0000
19.3800 1664.0000 1.0000
19.4000 1564.0000 1.0000
19.4200 1516.0000 1.0000
19.4400 1575.0000 1.0000
19.4600 1550.0000 1.0000
19.4800 1577.0000 1.0000
19.5000 1488.0000 1.0000
19.5200 1513.0000 1.0000
19.5400 1582.0000 1.0000
19.5600 1607.0000 1.0000
19.5800 1540.0000 1.0000
19.6000 1542.0000 1.0000
19.6200 1557.0000 1.0000
19.6400 1545.0000 1.0000
19.6600 1585.0000 1.0000
19.6800 1464.0000 1.0000
19.7000 1551.0000 1.0000
19.7200 1561.0000 1.0000
19.7400 1518.0000 1.0000
19.7600 1597.0000 1.0000
19.7800 1634.0000 1.0000
19.8000 1607.0000 1.0000
19.8200 1563.0000 1.0000
19.8400 1507.0000 1.0000
19.8600 1525.0000 1.0000
19.8800 1533.0000 1.0000
19.9000 1493.0000 1.0000
19.9200 1625.0000 1.0000
19.9400 1489.0000 1.0000
19.9600 1523.0000 1.0000
19.9800 1512.0000 1.0000
20.0000 1548.0000 1.0000
20.0200 1500.0000 1.0000
20.0400 1543.0000 1.0000
20.0600 1544.0000 1.0000
20.0800 1488.0000 1.0000
20.1000 1489.0000 1.0000
20.1200 1511.0000 1.0000
20.1400 1594.0000 1.0000
20.1600 1547.0000 1.0000
20.1800 1547.0000 1.0000
20.2000 1519.0000 1.0000
20.2200 1530.0000 1.0000
20.2400 1512.0000 1.0000
20.2600 1527.0000 1.0000
20.2800 1512.0000 1.0000
20.3000 1502.0000 1.0000
20.3200 1580.0000 1.0000
20.3400 1511.0000 1.0000
20.3600 1580.0000 1.0000
20.3800 1487.0000 1.0000
20.4000 1550.0000 1.0000
20.4200 1530.0000 1.0000
20.4400 1459.0000 1.0000
20.4600 1493.0000 1.0000
20.4800 1521.0000 1.0000
20.5000 1483.0000 1.0000
20.5200 1533.0000 1.0000
20.5400 1465.0000 1.0000
20.5600 1532.0000 1.0000
20.5800 1451.0000 1.0000
20.6000 1514.0000 1.0000
20.6200 1471.0000 1.0000
20.6400 1496.0000 1.0000
20.6600 1509.0000 1.0000
20.6800 1520.0000 1.0000
20.7000 1565.0000 1.0000
20.7200 1519.0000 1.0000
20.7400 1475.0000 1.0000
20.7600 1593.0000 1.0000
20.7800 1460.0000 1.0000
20.8000 1473.0000 1.0000
20.8200 1492.0000 1.0000
20.8400 1486.0000 1.0000
20.8600 1513.0000 1.0000
20.8800 1512.0000 1.0000
20.9000 1526.0000 1.0000
20.9200 1533.0000 1.0000
20.9400 1473.0000 1.0000
20.9600 1539.0000 1.0000
20.9800 1484.0000 1.0000
21.0000 1439.0000 1.0000
21.0200 1453.0000 1.0000
21.0400 1465.0000 1.0000
21.0600 1497.0000 1.0000
21.0800 1481.0000 1.0000
21.1000 1437.0000 1.0000
21.1200 1443.0000 1.0000
21.1400 1398.0000 1.0000
21.1600 1439.0000 1.0000
21.1800 1507.0000 1.0000
21.2000 1441.0000 1.0000
21.2200 1440.0000 1.0000
21.2400 1469.0000 1.0000
21.2600 1396.0000 1.0000
21.2800 1498.0000 1.0000
21.3000 1448.0000 1.0000
21.3200 1451.0000 1.0000
21.3400 1480.0000 1.0000
21.3600 1554.0000 1.0000
21.3800 1515.0000 1.0000
21.4000 1425.0000 1.0000
21.4200 1411.0000 1.0000
21.4400 1499.0000 1.0000
21.4600 1504.0000 1.0000
21.4800 1472.0000 1.0000
21.5000 1490.0000 1.0000
21.5200 1460.0000 1.0000
21.5400 1424.0000 1.0000
21.5600 1432.0000 1.0000
21.5800 1480.0000 1.0000
21.6000 1424.0000 1.0000
21.6200 1468.0000 1.0000
21.6400 1436.0000 1.0000
21.6600 1404.0000 1.0000
21.6800 1529.0000 1.0000
21.7000 1405.0000 1.0000
21.7200 1392.0000 1.0000
21.7400 1476.0000 1.0000
21.7600 1417.0000 1.0000
21.7800 1428.0000 1.0000
21.8000 1455.0000 1.0000
21.8200 1402.0000 1.0000
21.8400 1476.0000 1.0000
21.8600 1382.0000 1.0000
21.8800 1463.0000 1.0000
21.9000 1473.0000 1.0000
21.9200 1471.0000 1.0000
21.9400 1433.0000 1.0000
21.9600 1453.0000 1.0000
21.9800 1441.0000 1.0000
22.0000 1515.0000 1.0000
22.0200 1416.0000 1.0000
22.0400 1436.0000 1.0000
22.0600 1430.0000 1.0000
22.0800 1423.0000 1.0000
22.1000 1414.0000 1.0000
22.1200 1453.0000 1.0000
22.1400 1479.0000 1.0000
22.1600 1472.0000 1.0000
22.1800 1382.0000 1.0000
22.2000 1408.0000 1.0000
22.2200 1434.0000 1.0000
22.2400 1404.0000 1.0000
22.2600 1423.0000 1.0000
22.2800 1425.0000 1.0000
22.3000 1401.0000 1.0000
22.3200 1474.0000 1.0000
22.3400 1361.0000 1.0000
22.3600 1492.0000 1.0000
22.3800 1447.0000 1.0000
22.4000 1373.0000 1.0000
22.4200 1459.0000 1.0000
22.4400 1446.0000 1.0000
22.4600 1495.0000 1.0000
22.4800 1418.0000 1.0000
22.5000 1453.0000 1.0000
22.5200 1339.0000 1.0000
22.5400 1427.0000 1.0000
22.5600 1335.0000 1.0000
22.5800 1374.0000 1.0000
22.6000 1360.0000 1.0000
22.6200 1273.0000 1.0000
22.6400 1449.0000 1.0000
22.6600 1380.0000 1.0000
22.6800 1421.0000 1.0000
22.7000 1444.0000 1.0000
22.7200 1425.0000 1.0000
22.7400 1457.0000 1.0000
22.7600 1455.0000 1.0000
22.7800 1389.0000 1.0000
22.8000 1481.0000 1.0000
22.8200 1438.0000 1.0000
22.8400 1379.0000 1.0000
22.8600 1388.0000 1.0000
22.8800 1395.0000 1.0000
22.9000 1389.0000 1.0000
22.9200 1445.0000 1.0000
22.9400 1382.0000 1.0000
22.9600 1381.0000 1.0000
22.9800 1446.0000 1.0000
23.0000 1364.0000 1.0000
23.0200 1384.0000 1.0000
23.0400 1417.0000 1.0000
23.0600 1375.0000 1.0000
23.0800 1379.0000 1.0000
23.1000 1399.0000 1.0000
23.1200 1379.0000 1.0000
23.1400 1367.0000 1.0000
23.1600 1379.0000 1.0000
23.1800 1354.0000 1.0000
23.2000 1292.0000 1.0000
23.2200 1425.0000 1.0000
23.2400 1410.0000 1.0000
23.2600 1432.0000 1.0000
23.2800 1375.0000 1.0000
23.3000 1370.0000 1.0000
23.3200 1409.0000 1.0000
23.3400 1373.0000 1.0000
23.3600 1349.0000 1.0000
23.3800 1361.0000 1.0000
23.4000 1336.0000 1.0000
23.4200 1360.0000 1.0000
23.4400 1370.0000 1.0000
23.4600 1373.0000 1.0000
23.4800 1329.0000 1.0000
23.5000 1342.0000 1.0000
23.5200 1395.0000 1.0000
23.5400 1356.0000 1.0000
23.5600 1379.0000 1.0000
23.5800 1468.0000 1.0000
23.6000 1383.0000 1.0000
23.6200 1378.0000 1.0000
23.6400 1365.0000 1.0000
23.6600 1390.0000 1.0000
23.6800 1301.0000 1.0000
23.7000 1336.0000 1.0000
23.7200 1347.0000 1.0000
23.7400 1357.0000 1.0000
23.7600 1337.0000 1.0000
23.7800 1372.0000 1.0000
23.8000 1390.0000 1.0000
23.8200 1297.0000 1.0000
23.8400 1260.0000 1.0000
23.8600 1306.0000 1.0000
23.8800 1310.0000 1.0000
23.9000 1349.0000 1.0000
23.9200 1389.0000 1.0000
23.9400 1309.0000 1.0000
23.9600 1320.0000 1.0000
23.9800 1344.0000 1.0000
24.0000 1387.0000 1.0000
24.0200 1365.0000 1.0000
24.0400 1373.0000 1.0000
24.0600 1398.0000 1.0000
24.0800 1324.0000 1.0000
24.1000 1326.0000 1.0000
24.1200 1336.0000 1.0000
24.1400 1390.0000 1.0000
24.1600 1395.0000 1.0000
24.1800 1248.0000 1.0000
24.2000 1284.0000 1.0000
24.2200 1383.0000 1.0000
24.2400 1340.0000 1.0000
24.2600 1315.0000 1.0000
24.2800 1319.0000 1.0000
24.3000 1325.0000 1.0000
24.3200 1319.0000 1.0000
24.3400 1333.0000 1.0000
24.3600 1233.0000 1.0000
24.3800 1336.0000 1.0000
24.4000 1364.0000 1.0000
24.4200 1344.0000 1.0000
24.4400 1253.0000 1.0000
24.4600 1356.0000 1.0000
24.4800 1291.0000 1.0000
24.5000 1312.0000 1.0000
24.5200 1369.0000 1.0000
24.5400 1337.0000 1.0000
24.5600 1352.0000 1.0000
24.5800 1316.0000 1.0000
24.6000 1296.0000 1.0000
24.6200 1328.0000 1.0000
24.6400 1315.0000 1.0000
24.6600 1352.0000 1.0000
24.6800 1307.0000 1.0000
24.7000 1334.0000 1.0000
24.7200 1335.0000 1.0000
24.7400 1270.0000 1.0000
24.7600 1281.0000 1.0000
24.7800 1356.0000 1.0000
24.8000 1355.0000 1.0000
24.8200 1304.0000 1.0000
24.8400 1335.0000 1.0000
24.8600 1286.0000 1.0000
24.8800 1286.0000 1.0000
24.9000 1315.0000 1.0000
24.9200 1347.0000 1.0000
24.9400 1401.0000 1.0000
24.9600 1272.0000 1.0000
24.9800 1346.0000 1.0000
25.0000 1272.0000 1.0000
25.0200 1370.0000 1.0000
25.0400 1274.0000 1.0000
25.0600 1369.0000 1.0000
25.0800 1287.0000 1.0000
25.1000 1242.0000 1.0000
25.1200 1300.0000 1.0000
25.1400 1248.0000 1.0000
25.1600 1351.0000 1.0000
25.1800 1307.0000 1.0000
25.2000 1343.0000 1.0000
25.2200 1246.0000 1.0000
25.2400 1238.0000 1.0000
25.2600 1325.0000 1.0000
25.2800 1232.0000 1.0000
25.3000 1352.0000 1.0000
25.3200 1385.0000 1.0000
25.3400 1337.0000 1.0000
25.3600 1253.0000 1.0000
25.3800 1271.0000 1.0000
25.4000 1287.0000 1.0000
25.4200 1361.0000 1.0000
25.4400 1296.0000 1.0000
25.4600 1233.0000 1.0000
25.4800 1250.0000 1.0000
25.5000 1286.0000 1.0000
25.5200 1308.0000 1.0000
25.5400 1298.0000 1.0000
25.5600 1246.0000 1.0000
25.5800 1239.0000 1.0000
25.6000 1258.0000 1.0000
25.6200 1250.0000 1.0000
25.6400 1275.0000 1.0000
25.6600 1227.0000 1.0000
25.6800 1243.0000 1.0000
25.7000 1275.0000 1.0000
25.7200 1243.0000 1.0000
25.7400 1379.0000 1.0000
25.7600 1278.0000 1.0000
25.7800 1238.0000 1.0000
25.8000 1266.0000 1.0000
25.8200 1227.0000 1.0000
25.8400 1281.0000 1.0000
25.8600 1307.0000 1.0000
25.8800 1207.0000 1.0000
25.9000 1201.0000 1.0000
25.9200 1243.0000 1.0000
25.9400 1298.0000 1.0000
25.9600 1300.0000 1.0000
25.9800 1246.0000 1.0000
26.0000 1287.0000 1.0000
26.0200 1320.0000 1.0000
26.0400 1247.0000 1.0000
26.0600 1229.0000 1.0000
26.0800 1235.0000 1.0000
26.1000 1251.0000 1.0000
26.1200 1306.0000 1.0000
26.1400 1278.0000 1.0000
26.1600 1227.0000 1.0000
26.1800 1213.0000 1.0000
26.2000 1276.0000 1.0000
26.2200 1230.0000 1.0000
26.2400 1189.0000 1.0000
26.2600 1227.0000 1.0000
26.2800 1229.0000 1.0000
26.3000 1264.0000 1.0000
26.3200 1288.0000 1.0000
26.3400 1210.0000 1.0000
26.3600 1197.0000 1.0000
26.3800 1235.0000 1.0000
26.4000 1228.0000 1.0000
26.4200 1205.0000 1.0000
26.4400 1255.0000 1.0000
26.4600 1237.0000 1.0000
26.4800 1265.0000 1.0000
26.5000 1286.0000 1.0000
26.5200 1201.0000 1.0000
26.5400 1235.0000 1.0000
26.5600 1252.0000 1.0000
26.5800 1195.0000 1.0000
26.6000 1223.0000 1.0000
26.6200 1285.0000 1.0000
26.6400 1241.0000 1.0000
26.6600 1236.0000 1.0000
26.6800 1201.0000 1.0000
26.7000 1219.0000 1.0000
26.7200 1326.0000 1.0000
26.7400 1283.0000 1.0000
26.7600 1296.0000 1.0000
26.7800 1193.0000 1.0000
26.8000 1261.0000 1.0000
26.8200 1327.0000 1.0000
26.8400 1167.0000 1.0000
26.8600 1231.0000 1.0000
26.8800 1217.0000 1.0000
26.9000 1236.0000 1.0000
26.9200 1198.0000 1.0000
26.9400 1218.0000 1.0000
26.9600 1221.0000 1.0000
26.9800 1206.0000 1.0000
27.0000 1259.0000 1.0000
27.0200 1207.0000 1.0000
27.0400 1203.0000 1.0000
27.0600 1225.0000 1.0000
27.0800 1189.0000 1.0000
27.1000 1218.0000 1.0000
27.1200 1158.0000 1.0000
27.1400 1306.0000 1.0000
27.1600 1183.0000 1.0000
27.1800 1207.0000 1.0000
27.2000 1234.0000 1.0000
27.2200 1241.0000 1.0000
27.2400 1173.0000 1.0000
27.2600 1256.0000 1.0000
27.2800 1169.0000 1.0000
27.3000 1156.0000 1.0000
27.3200 1236.0000 1.0000
27.3400 1191.0000 1.0000
27.3600 1235.0000 1.0000
27.3800 1200.0000 1.0000
27.4000 1216.0000 1.0000
27.4200 1159.0000 1.0000
27.4400 1249.0000 1.0000
27.4600 1217.0000 1.0000
27.4800 1235.0000 1.0000
27.5000 1226.0000 1.0000
27.5200 1211.0000 1.0000
27.5400 1214.0000 1.0000
27.5600 1269.0000 1.0000
27.5800 1211.0000 1.0000
27.6000 1234.0000 1.0000
27.6200 1243.0000 1.0000
27.6400 1187.0000 1.0000
27.6600 1189.0000 1.0000
27.6800 1308.0000 1.0000
27.7000 1264.0000 1.0000
27.7200 1238.0000 1.0000
27.7400 1285.0000 1.0000
27.7600 1207.0000 1.0000
27.7800 1257.0000 1.0000
27.8000 1239.0000 1.0000
27.8200 1246.0000 1.0000
27.8400 1257.0000 1.0000
27.8600 1239.0000 1.0000
27.8800 1223.0000 1.0000
27.9000 1242.0000 1.0000
27.9200 1184.0000 1.0000
27.9400 1242.0000 1.0000
27.9600 1222.0000 1.0000
27.9800 1243.0000 1.0000
28.0000 1212.0000 1.0000
28.0200 1301.0000 1.0000
28.0400 1262.0000 1.0000
28.0600 1259.0000 1.0000
28.0800 1248.0000 1.0000
28.1000 1255.0000 1.0000
28.1200 1297.0000 1.0000
28.1400 1306.0000 1.0000
28.1600 1296.0000 1.0000
28.1800 1229.0000 1.0000
28.2000 1295.0000 1.0000
28.2200 1402.0000 1.0000
28.2400 1282.0000 1.0000
28.2600 1280.0000 1.0000
28.2800 1322.0000 1.0000
28.3000 1295.0000 1.0000
28.3200 1416.0000 1.0000
28.3400 1373.0000 1.0000
28.3600 1410.0000 1.0000
28.3800 1381.0000 1.0000
28.4000 1431.0000 1.0000
28.4200 1428.0000 1.0000
28.4400 1412.0000 1.0000
28.4600 1554.0000 1.0000
28.4800 1517.0000 1.0000
28.5000 1559.0000 1.0000
28.5200 1521.0000 1.0000
28.5400 1509.0000 1.0000
28.5600 1608.0000 1.0000
28.5800 1534.0000 1.0000
28.6000 1571.0000 1.0000
28.6200 1566.0000 1.0000
28.6400 1521.0000 1.0000
28.6600 1594.0000 1.0000
28.6800 1592.0000 1.0000
28.7000 1567.0000 1.0000
28.7200 1625.0000 1.0000
28.7400 1646.0000 1.0000
28.7600 1609.0000 1.0000
28.7800 1553.0000 1.0000
28.8000 1620.0000 1.0000
28.8200 1594.0000 1.0000
28.8400 1581.0000 1.0000
28.8600 1663.0000 1.0000
28.8800 1638.0000 1.0000
28.9000 1652.0000 1.0000
28.9200 1565.0000 1.0000
28.9400 1540.0000 1.0000
28.9600 1586.0000 1.0000
28.9800 1656.0000 1.0000
29.0000 1614.0000 1.0000
29.0200 1658.0000 1.0000
29.0400 1618.0000 1.0000
29.0600 1577.0000 1.0000
29.0800 1571.0000 1.0000
29.1000 1593.0000 1.0000
29.1200 1598.0000 1.0000
29.1400 1598.0000 1.0000
29.1600 1573.0000 1.0000
29.1800 1580.0000 1.0000
29.2000 1539.0000 1.0000
29.2200 1533.0000 1.0000
29.2400 1510.0000 1.0000
29.2600 1489.0000 1.0000
29.2800 1506.0000 1.0000
29.3000 1403.0000 1.0000
29.3200 1386.0000 1.0000
29.3400 1451.0000 1.0000
29.3600 1371.0000 1.0000
29.3800 1308.0000 1.0000
29.4000 1283.0000 1.0000
29.4200 1322.0000 1.0000
29.4400 1372.0000 1.0000
29.4600 1337.0000 1.0000
29.4800 1299.0000 1.0000
29.5000 1337.0000 1.0000
29.5200 1310.0000 1.0000
29.5400 1200.0000 1.0000
29.5600 1321.0000 1.0000
29.5800 1293.0000 1.0000
29.6000 1222.0000 1.0000
29.6200 1177.0000 1.0000
29.6400 1314.0000 1.0000
29.6600 1175.0000 1.0000
29.6800 1230.0000 1.0000
29.7000 1198.0000 1.0000
29.7200 1112.0000 1.0000
29.7400 1212.0000 1.0000
29.7600 1144.0000 1.0000
29.7800 1176.0000 1.0000
29.8000 1183.0000 1.0000
29.8200 1182.0000 1.0000
29.8400 1220.0000 1.0000
29.8600 1132.0000 1.0000
29.8800 1123.0000 1.0000
29.9000 1190.0000 1.0000
29.9200 1108.0000 1.0000
29.9400 1121.0000 1.0000
29.9600 1138.0000 1.0000
29.9800 1158.0000 1.0000
30.0000 1150.0000 1.0000
*RAS_INT_END
*RAS_DATA_END